[2021-08-08 16:54:00,612] {taskinstance.py:896} INFO - Dependencies all met for <TaskInstance: popula_bd.verifica_arquivo 2021-08-08T19:53:49.953625+00:00 [queued]>
[2021-08-08 16:54:00,614] {taskinstance.py:896} INFO - Dependencies all met for <TaskInstance: popula_bd.verifica_arquivo 2021-08-08T19:53:49.953625+00:00 [queued]>
[2021-08-08 16:54:00,614] {taskinstance.py:1087} INFO - 
--------------------------------------------------------------------------------
[2021-08-08 16:54:00,614] {taskinstance.py:1088} INFO - Starting attempt 1 of 2
[2021-08-08 16:54:00,614] {taskinstance.py:1089} INFO - 
--------------------------------------------------------------------------------
[2021-08-08 16:54:00,618] {taskinstance.py:1107} INFO - Executing <Task(PythonOperator): verifica_arquivo> on 2021-08-08T19:53:49.953625+00:00
[2021-08-08 16:54:00,620] {standard_task_runner.py:52} INFO - Started process 14306 to run task
[2021-08-08 16:54:00,621] {standard_task_runner.py:76} INFO - Running: ['airflow', 'tasks', 'run', 'popula_bd', 'verifica_arquivo', '2021-08-08T19:53:49.953625+00:00', '--job-id', '42', '--pool', 'default_pool', '--raw', '--subdir', 'DAGS_FOLDER/popula.py', '--cfg-path', '/tmp/tmpylcwt431', '--error-file', '/tmp/tmpec817s7c']
[2021-08-08 16:54:00,622] {standard_task_runner.py:77} INFO - Job 42: Subtask verifica_arquivo
[2021-08-08 16:54:00,632] {logging_mixin.py:104} INFO - Running <TaskInstance: popula_bd.verifica_arquivo 2021-08-08T19:53:49.953625+00:00 [running]> on host DESKTOP-BEFA8CP.localdomain
[2021-08-08 16:54:00,645] {taskinstance.py:1300} INFO - Exporting the following env vars:
AIRFLOW_CTX_DAG_EMAIL=vh15fleury@hotmail.com
AIRFLOW_CTX_DAG_OWNER=victor hugo
AIRFLOW_CTX_DAG_ID=popula_bd
AIRFLOW_CTX_TASK_ID=verifica_arquivo
AIRFLOW_CTX_EXECUTION_DATE=2021-08-08T19:53:49.953625+00:00
AIRFLOW_CTX_DAG_RUN_ID=scheduled__2021-08-08T19:53:49.953625+00:00
[2021-08-08 16:54:00,680] {taskinstance.py:1501} ERROR - Task failed with exception
Traceback (most recent call last):
  File "/home/churebas/projetos/python-dev-test/.env/lib/python3.8/site-packages/airflow/models/taskinstance.py", line 1157, in _run_raw_task
    self._prepare_and_execute_task_with_callbacks(context, task)
  File "/home/churebas/projetos/python-dev-test/.env/lib/python3.8/site-packages/airflow/models/taskinstance.py", line 1331, in _prepare_and_execute_task_with_callbacks
    result = self._execute_task(context, task_copy)
  File "/home/churebas/projetos/python-dev-test/.env/lib/python3.8/site-packages/airflow/models/taskinstance.py", line 1361, in _execute_task
    result = task_copy.execute(context=context)
  File "/home/churebas/projetos/python-dev-test/.env/lib/python3.8/site-packages/airflow/operators/python.py", line 150, in execute
    return_value = self.execute_callable()
  File "/home/churebas/projetos/python-dev-test/.env/lib/python3.8/site-packages/airflow/operators/python.py", line 161, in execute_callable
    return self.python_callable(*self.op_args, **self.op_kwargs)
  File "/home/churebas/projetos/python-dev-test/airflow/dags/popula.py", line 26, in verifica_arquivo
    raise AirflowSkipException
NameError: name 'AirflowSkipException' is not defined
[2021-08-08 16:54:00,681] {taskinstance.py:1544} INFO - Marking task as UP_FOR_RETRY. dag_id=popula_bd, task_id=verifica_arquivo, execution_date=20210808T195349, start_date=20210808T195400, end_date=20210808T195400
[2021-08-08 16:54:00,690] {logging_mixin.py:104} WARNING - /home/churebas/projetos/python-dev-test/.env/lib/python3.8/site-packages/airflow/utils/email.py:102 PendingDeprecationWarning: Fetching SMTP credentials from configuration variables will be deprecated in a future release. Please set credentials using a connection instead.
[2021-08-08 16:54:00,690] {configuration.py:365} WARNING - section/key [smtp/smtp_user] not found in config
[2021-08-08 16:54:00,690] {email.py:208} INFO - Email alerting: attempt 1
[2021-08-08 16:54:00,691] {configuration.py:365} WARNING - section/key [smtp/smtp_user] not found in config
[2021-08-08 16:54:00,691] {email.py:208} INFO - Email alerting: attempt 1
[2021-08-08 16:54:00,691] {taskinstance.py:1557} ERROR - Failed to send email to: ['vh15fleury@hotmail.com']
Traceback (most recent call last):
  File "/home/churebas/projetos/python-dev-test/.env/lib/python3.8/site-packages/airflow/models/taskinstance.py", line 1157, in _run_raw_task
    self._prepare_and_execute_task_with_callbacks(context, task)
  File "/home/churebas/projetos/python-dev-test/.env/lib/python3.8/site-packages/airflow/models/taskinstance.py", line 1331, in _prepare_and_execute_task_with_callbacks
    result = self._execute_task(context, task_copy)
  File "/home/churebas/projetos/python-dev-test/.env/lib/python3.8/site-packages/airflow/models/taskinstance.py", line 1361, in _execute_task
    result = task_copy.execute(context=context)
  File "/home/churebas/projetos/python-dev-test/.env/lib/python3.8/site-packages/airflow/operators/python.py", line 150, in execute
    return_value = self.execute_callable()
  File "/home/churebas/projetos/python-dev-test/.env/lib/python3.8/site-packages/airflow/operators/python.py", line 161, in execute_callable
    return self.python_callable(*self.op_args, **self.op_kwargs)
  File "/home/churebas/projetos/python-dev-test/airflow/dags/popula.py", line 26, in verifica_arquivo
    raise AirflowSkipException
NameError: name 'AirflowSkipException' is not defined

During handling of the above exception, another exception occurred:

Traceback (most recent call last):
  File "/home/churebas/projetos/python-dev-test/.env/lib/python3.8/site-packages/airflow/models/taskinstance.py", line 1896, in email_alert
    send_email(self.task.email, subject, html_content)
  File "/home/churebas/projetos/python-dev-test/.env/lib/python3.8/site-packages/airflow/utils/email.py", line 55, in send_email
    return backend(
  File "/home/churebas/projetos/python-dev-test/.env/lib/python3.8/site-packages/airflow/utils/email.py", line 102, in send_email_smtp
    send_mime_email(e_from=smtp_mail_from, e_to=recipients, mime_msg=msg, conn_id=conn_id, dryrun=dryrun)
  File "/home/churebas/projetos/python-dev-test/.env/lib/python3.8/site-packages/airflow/utils/email.py", line 210, in send_mime_email
    conn = _get_smtp_connection(smtp_host, smtp_port, smtp_timeout, smtp_ssl)
  File "/home/churebas/projetos/python-dev-test/.env/lib/python3.8/site-packages/airflow/utils/email.py", line 244, in _get_smtp_connection
    else smtplib.SMTP(host=host, port=port, timeout=timeout)
  File "/usr/lib/python3.8/smtplib.py", line 255, in __init__
    (code, msg) = self.connect(host, port)
  File "/usr/lib/python3.8/smtplib.py", line 339, in connect
    self.sock = self._get_socket(host, port, self.timeout)
  File "/usr/lib/python3.8/smtplib.py", line 310, in _get_socket
    return socket.create_connection((host, port), timeout,
  File "/usr/lib/python3.8/socket.py", line 808, in create_connection
    raise err
  File "/usr/lib/python3.8/socket.py", line 796, in create_connection
    sock.connect(sa)
ConnectionRefusedError: [Errno 111] Connection refused

During handling of the above exception, another exception occurred:

Traceback (most recent call last):
  File "/home/churebas/projetos/python-dev-test/.env/lib/python3.8/site-packages/airflow/models/taskinstance.py", line 1555, in handle_failure
    self.email_alert(error)
  File "/home/churebas/projetos/python-dev-test/.env/lib/python3.8/site-packages/airflow/models/taskinstance.py", line 1898, in email_alert
    send_email(self.task.email, subject, html_content_err)
  File "/home/churebas/projetos/python-dev-test/.env/lib/python3.8/site-packages/airflow/utils/email.py", line 55, in send_email
    return backend(
  File "/home/churebas/projetos/python-dev-test/.env/lib/python3.8/site-packages/airflow/utils/email.py", line 102, in send_email_smtp
    send_mime_email(e_from=smtp_mail_from, e_to=recipients, mime_msg=msg, conn_id=conn_id, dryrun=dryrun)
  File "/home/churebas/projetos/python-dev-test/.env/lib/python3.8/site-packages/airflow/utils/email.py", line 210, in send_mime_email
    conn = _get_smtp_connection(smtp_host, smtp_port, smtp_timeout, smtp_ssl)
  File "/home/churebas/projetos/python-dev-test/.env/lib/python3.8/site-packages/airflow/utils/email.py", line 244, in _get_smtp_connection
    else smtplib.SMTP(host=host, port=port, timeout=timeout)
  File "/usr/lib/python3.8/smtplib.py", line 255, in __init__
    (code, msg) = self.connect(host, port)
  File "/usr/lib/python3.8/smtplib.py", line 339, in connect
    self.sock = self._get_socket(host, port, self.timeout)
  File "/usr/lib/python3.8/smtplib.py", line 310, in _get_socket
    return socket.create_connection((host, port), timeout,
  File "/usr/lib/python3.8/socket.py", line 808, in create_connection
    raise err
  File "/usr/lib/python3.8/socket.py", line 796, in create_connection
    sock.connect(sa)
ConnectionRefusedError: [Errno 111] Connection refused
[2021-08-08 16:54:00,713] {local_task_job.py:149} INFO - Task exited with return code 1
