[2021-08-08 17:03:58,545] {taskinstance.py:896} INFO - Dependencies all met for <TaskInstance: popula_bd.popula_adult 2021-08-08T20:03:46.180049+00:00 [queued]>
[2021-08-08 17:03:58,547] {taskinstance.py:896} INFO - Dependencies all met for <TaskInstance: popula_bd.popula_adult 2021-08-08T20:03:46.180049+00:00 [queued]>
[2021-08-08 17:03:58,547] {taskinstance.py:1087} INFO - 
--------------------------------------------------------------------------------
[2021-08-08 17:03:58,547] {taskinstance.py:1088} INFO - Starting attempt 1 of 2
[2021-08-08 17:03:58,547] {taskinstance.py:1089} INFO - 
--------------------------------------------------------------------------------
[2021-08-08 17:03:58,551] {taskinstance.py:1107} INFO - Executing <Task(PythonOperator): popula_adult> on 2021-08-08T20:03:46.180049+00:00
[2021-08-08 17:03:58,553] {standard_task_runner.py:52} INFO - Started process 19668 to run task
[2021-08-08 17:03:58,554] {standard_task_runner.py:76} INFO - Running: ['airflow', 'tasks', 'run', 'popula_bd', 'popula_adult', '2021-08-08T20:03:46.180049+00:00', '--job-id', '137', '--pool', 'default_pool', '--raw', '--subdir', 'DAGS_FOLDER/popula.py', '--cfg-path', '/tmp/tmpeaeti9l5', '--error-file', '/tmp/tmpzikjui9w']
[2021-08-08 17:03:58,554] {standard_task_runner.py:77} INFO - Job 137: Subtask popula_adult
[2021-08-08 17:03:58,565] {logging_mixin.py:104} INFO - Running <TaskInstance: popula_bd.popula_adult 2021-08-08T20:03:46.180049+00:00 [running]> on host DESKTOP-BEFA8CP.localdomain
[2021-08-08 17:03:58,579] {taskinstance.py:1300} INFO - Exporting the following env vars:
AIRFLOW_CTX_DAG_EMAIL=vh15fleury@hotmail.com
AIRFLOW_CTX_DAG_OWNER=victor hugo
AIRFLOW_CTX_DAG_ID=popula_bd
AIRFLOW_CTX_TASK_ID=popula_adult
AIRFLOW_CTX_EXECUTION_DATE=2021-08-08T20:03:46.180049+00:00
AIRFLOW_CTX_DAG_RUN_ID=scheduled__2021-08-08T20:03:46.180049+00:00
[2021-08-08 17:03:58,580] {taskinstance.py:1501} ERROR - Task failed with exception
Traceback (most recent call last):
  File "/home/churebas/projetos/python-dev-test/.env/lib/python3.8/site-packages/airflow/models/taskinstance.py", line 1157, in _run_raw_task
    self._prepare_and_execute_task_with_callbacks(context, task)
  File "/home/churebas/projetos/python-dev-test/.env/lib/python3.8/site-packages/airflow/models/taskinstance.py", line 1331, in _prepare_and_execute_task_with_callbacks
    result = self._execute_task(context, task_copy)
  File "/home/churebas/projetos/python-dev-test/.env/lib/python3.8/site-packages/airflow/models/taskinstance.py", line 1361, in _execute_task
    result = task_copy.execute(context=context)
  File "/home/churebas/projetos/python-dev-test/.env/lib/python3.8/site-packages/airflow/operators/python.py", line 150, in execute
    return_value = self.execute_callable()
  File "/home/churebas/projetos/python-dev-test/.env/lib/python3.8/site-packages/airflow/operators/python.py", line 161, in execute_callable
    return self.python_callable(*self.op_args, **self.op_kwargs)
  File "/home/churebas/projetos/python-dev-test/airflow/dags/popula.py", line 35, in percorre_df
    df = pd.read_csv(arquivo)
  File "/home/churebas/projetos/python-dev-test/.env/lib/python3.8/site-packages/pandas/util/_decorators.py", line 311, in wrapper
    return func(*args, **kwargs)
  File "/home/churebas/projetos/python-dev-test/.env/lib/python3.8/site-packages/pandas/io/parsers/readers.py", line 586, in read_csv
    return _read(filepath_or_buffer, kwds)
  File "/home/churebas/projetos/python-dev-test/.env/lib/python3.8/site-packages/pandas/io/parsers/readers.py", line 482, in _read
    parser = TextFileReader(filepath_or_buffer, **kwds)
  File "/home/churebas/projetos/python-dev-test/.env/lib/python3.8/site-packages/pandas/io/parsers/readers.py", line 811, in __init__
    self._engine = self._make_engine(self.engine)
  File "/home/churebas/projetos/python-dev-test/.env/lib/python3.8/site-packages/pandas/io/parsers/readers.py", line 1040, in _make_engine
    return mapping[engine](self.f, **self.options)  # type: ignore[call-arg]
  File "/home/churebas/projetos/python-dev-test/.env/lib/python3.8/site-packages/pandas/io/parsers/c_parser_wrapper.py", line 51, in __init__
    self._open_handles(src, kwds)
  File "/home/churebas/projetos/python-dev-test/.env/lib/python3.8/site-packages/pandas/io/parsers/base_parser.py", line 222, in _open_handles
    self.handles = get_handle(
  File "/home/churebas/projetos/python-dev-test/.env/lib/python3.8/site-packages/pandas/io/common.py", line 701, in get_handle
    handle = open(
FileNotFoundError: [Errno 2] No such file or directory: '/home/churebas/projetos/python-dev-test/data/adult.csv'
[2021-08-08 17:03:58,581] {taskinstance.py:1544} INFO - Marking task as UP_FOR_RETRY. dag_id=popula_bd, task_id=popula_adult, execution_date=20210808T200346, start_date=20210808T200358, end_date=20210808T200358
[2021-08-08 17:03:58,588] {logging_mixin.py:104} WARNING - /home/churebas/projetos/python-dev-test/.env/lib/python3.8/site-packages/airflow/utils/email.py:102 PendingDeprecationWarning: Fetching SMTP credentials from configuration variables will be deprecated in a future release. Please set credentials using a connection instead.
[2021-08-08 17:03:58,588] {configuration.py:365} WARNING - section/key [smtp/smtp_user] not found in config
[2021-08-08 17:03:58,588] {email.py:208} INFO - Email alerting: attempt 1
[2021-08-08 17:03:58,589] {configuration.py:365} WARNING - section/key [smtp/smtp_user] not found in config
[2021-08-08 17:03:58,589] {email.py:208} INFO - Email alerting: attempt 1
[2021-08-08 17:03:58,589] {taskinstance.py:1557} ERROR - Failed to send email to: ['vh15fleury@hotmail.com']
Traceback (most recent call last):
  File "/home/churebas/projetos/python-dev-test/.env/lib/python3.8/site-packages/airflow/models/taskinstance.py", line 1157, in _run_raw_task
    self._prepare_and_execute_task_with_callbacks(context, task)
  File "/home/churebas/projetos/python-dev-test/.env/lib/python3.8/site-packages/airflow/models/taskinstance.py", line 1331, in _prepare_and_execute_task_with_callbacks
    result = self._execute_task(context, task_copy)
  File "/home/churebas/projetos/python-dev-test/.env/lib/python3.8/site-packages/airflow/models/taskinstance.py", line 1361, in _execute_task
    result = task_copy.execute(context=context)
  File "/home/churebas/projetos/python-dev-test/.env/lib/python3.8/site-packages/airflow/operators/python.py", line 150, in execute
    return_value = self.execute_callable()
  File "/home/churebas/projetos/python-dev-test/.env/lib/python3.8/site-packages/airflow/operators/python.py", line 161, in execute_callable
    return self.python_callable(*self.op_args, **self.op_kwargs)
  File "/home/churebas/projetos/python-dev-test/airflow/dags/popula.py", line 35, in percorre_df
    df = pd.read_csv(arquivo)
  File "/home/churebas/projetos/python-dev-test/.env/lib/python3.8/site-packages/pandas/util/_decorators.py", line 311, in wrapper
    return func(*args, **kwargs)
  File "/home/churebas/projetos/python-dev-test/.env/lib/python3.8/site-packages/pandas/io/parsers/readers.py", line 586, in read_csv
    return _read(filepath_or_buffer, kwds)
  File "/home/churebas/projetos/python-dev-test/.env/lib/python3.8/site-packages/pandas/io/parsers/readers.py", line 482, in _read
    parser = TextFileReader(filepath_or_buffer, **kwds)
  File "/home/churebas/projetos/python-dev-test/.env/lib/python3.8/site-packages/pandas/io/parsers/readers.py", line 811, in __init__
    self._engine = self._make_engine(self.engine)
  File "/home/churebas/projetos/python-dev-test/.env/lib/python3.8/site-packages/pandas/io/parsers/readers.py", line 1040, in _make_engine
    return mapping[engine](self.f, **self.options)  # type: ignore[call-arg]
  File "/home/churebas/projetos/python-dev-test/.env/lib/python3.8/site-packages/pandas/io/parsers/c_parser_wrapper.py", line 51, in __init__
    self._open_handles(src, kwds)
  File "/home/churebas/projetos/python-dev-test/.env/lib/python3.8/site-packages/pandas/io/parsers/base_parser.py", line 222, in _open_handles
    self.handles = get_handle(
  File "/home/churebas/projetos/python-dev-test/.env/lib/python3.8/site-packages/pandas/io/common.py", line 701, in get_handle
    handle = open(
FileNotFoundError: [Errno 2] No such file or directory: '/home/churebas/projetos/python-dev-test/data/adult.csv'

During handling of the above exception, another exception occurred:

Traceback (most recent call last):
  File "/home/churebas/projetos/python-dev-test/.env/lib/python3.8/site-packages/airflow/models/taskinstance.py", line 1896, in email_alert
    send_email(self.task.email, subject, html_content)
  File "/home/churebas/projetos/python-dev-test/.env/lib/python3.8/site-packages/airflow/utils/email.py", line 55, in send_email
    return backend(
  File "/home/churebas/projetos/python-dev-test/.env/lib/python3.8/site-packages/airflow/utils/email.py", line 102, in send_email_smtp
    send_mime_email(e_from=smtp_mail_from, e_to=recipients, mime_msg=msg, conn_id=conn_id, dryrun=dryrun)
  File "/home/churebas/projetos/python-dev-test/.env/lib/python3.8/site-packages/airflow/utils/email.py", line 210, in send_mime_email
    conn = _get_smtp_connection(smtp_host, smtp_port, smtp_timeout, smtp_ssl)
  File "/home/churebas/projetos/python-dev-test/.env/lib/python3.8/site-packages/airflow/utils/email.py", line 244, in _get_smtp_connection
    else smtplib.SMTP(host=host, port=port, timeout=timeout)
  File "/usr/lib/python3.8/smtplib.py", line 255, in __init__
    (code, msg) = self.connect(host, port)
  File "/usr/lib/python3.8/smtplib.py", line 339, in connect
    self.sock = self._get_socket(host, port, self.timeout)
  File "/usr/lib/python3.8/smtplib.py", line 310, in _get_socket
    return socket.create_connection((host, port), timeout,
  File "/usr/lib/python3.8/socket.py", line 808, in create_connection
    raise err
  File "/usr/lib/python3.8/socket.py", line 796, in create_connection
    sock.connect(sa)
ConnectionRefusedError: [Errno 111] Connection refused

During handling of the above exception, another exception occurred:

Traceback (most recent call last):
  File "/home/churebas/projetos/python-dev-test/.env/lib/python3.8/site-packages/airflow/models/taskinstance.py", line 1555, in handle_failure
    self.email_alert(error)
  File "/home/churebas/projetos/python-dev-test/.env/lib/python3.8/site-packages/airflow/models/taskinstance.py", line 1898, in email_alert
    send_email(self.task.email, subject, html_content_err)
  File "/home/churebas/projetos/python-dev-test/.env/lib/python3.8/site-packages/airflow/utils/email.py", line 55, in send_email
    return backend(
  File "/home/churebas/projetos/python-dev-test/.env/lib/python3.8/site-packages/airflow/utils/email.py", line 102, in send_email_smtp
    send_mime_email(e_from=smtp_mail_from, e_to=recipients, mime_msg=msg, conn_id=conn_id, dryrun=dryrun)
  File "/home/churebas/projetos/python-dev-test/.env/lib/python3.8/site-packages/airflow/utils/email.py", line 210, in send_mime_email
    conn = _get_smtp_connection(smtp_host, smtp_port, smtp_timeout, smtp_ssl)
  File "/home/churebas/projetos/python-dev-test/.env/lib/python3.8/site-packages/airflow/utils/email.py", line 244, in _get_smtp_connection
    else smtplib.SMTP(host=host, port=port, timeout=timeout)
  File "/usr/lib/python3.8/smtplib.py", line 255, in __init__
    (code, msg) = self.connect(host, port)
  File "/usr/lib/python3.8/smtplib.py", line 339, in connect
    self.sock = self._get_socket(host, port, self.timeout)
  File "/usr/lib/python3.8/smtplib.py", line 310, in _get_socket
    return socket.create_connection((host, port), timeout,
  File "/usr/lib/python3.8/socket.py", line 808, in create_connection
    raise err
  File "/usr/lib/python3.8/socket.py", line 796, in create_connection
    sock.connect(sa)
ConnectionRefusedError: [Errno 111] Connection refused
[2021-08-08 17:03:58,606] {local_task_job.py:149} INFO - Task exited with return code 1
